<?xml version="1.0" encoding="utf-8"?>
<!-- This URDF was automatically created by SolidWorks to URDF Exporter! Originally created by
Stephen Brawner (brawner@gmail.com) 
     Commit Version: 1.6.0-1-g15f4949  Build Version: 1.6.7594.29634
     For more information, please see http://wiki.ros.org/sw_urdf_exporter -->
<robot
  name="car_4wd">
  <link
    name="base_link">
    <inertial>
      <origin
        xyz="0.00026343 -1.5536E-11 0.0056311"
        rpy="0 0 0" />
      <mass
        value="0.62938" />
      <inertia
        ixx="0.0021443"
        ixy="5.5259E-11"
        ixz="-1.8826E-05"
        iyy="0.0022725"
        iyz="-4.0513E-15"
        izz="0.0042455" />
    </inertial>
    <visual>
      <origin
        xyz="0 0 0"
        rpy="0 0 0" />
      <geometry>
        <mesh
          filename="package://car_4wd/meshes/base_link.STL" />
      </geometry>
      <material
        name="">
        <color
          rgba="0.75294 0.75294 0.75294 1" />
      </material>
    </visual>
    <collision>
      <origin
        xyz="0 0 0"
        rpy="0 0 0" />
      <geometry>
        <mesh
          filename="package://car_4wd/meshes/base_link.STL" />
      </geometry>
    </collision>
  </link>
  <link
    name="rim_front_left_Link">
    <inertial>
      <origin
        xyz="0 -1.1102E-16 0.013812"
        rpy="0 0 0" />
      <mass
        value="0.045828" />
      <inertia
        ixx="0.0001"
        ixy="0.0"
        ixz="0.0"
        iyy="0.0001"
        iyz="0.0"
        izz="0.0002" />
    </inertial>
    <visual>
      <origin
        xyz="0 0 0"
        rpy="0 0 0" />
      <geometry>
        <mesh
          filename="package://car_4wd/meshes/rim_front_left_Link.STL" />
      </geometry>
      <material
        name="">
        <color
          rgba="0.79216 0.81961 0.93333 1" />
      </material>
    </visual>
    <collision>
      <origin
        xyz="0 0 0"
        rpy="0 0 0" />
      <geometry>
        <mesh
          filename="package://car_4wd/meshes/rim_front_left_Link.STL" />
      </geometry>
    </collision>
  </link>
  <joint
    name="rim_front_left_joint"
    type="continuous">
    <origin
      xyz="0.11977 0.12038 -0.0255"
      rpy="1.5708 0 -0.7854" />
    <parent
      link="base_link" />
    <child
      link="rim_front_left_Link" />
    <axis
      xyz="0 0 -1" />
    <dynamics
      damping="0.01"
      friction="0.01" />
  </joint>
  <link
    name="roller_e_rim_front_left_link">
    <inertial>
      <origin
        xyz="-2.7756E-17 0 0"
        rpy="0 0 0" />
      <mass
        value="0.0066143" />
      <inertia
        ixx="0.0001"
        ixy="0.0"
        ixz="0.0"
        iyy="0.0001"
        iyz="0.0"
        izz="0.0002" />
    </inertial>
    <visual>
      <origin
        xyz="0 0 0"
        rpy="0 0 0" />
      <geometry>
        <mesh
          filename="package://car_4wd/meshes/roller_e_rim_front_left_link.STL" />
      </geometry>
      <material
        name="">
        <color
          rgba="0.29804 0.29804 0.29804 1" />
      </material>
    </visual>
    <collision>
      <origin
        xyz="0 0 0"
        rpy="0 0 0" />
      <geometry>
        <mesh
          filename="package://car_4wd/meshes/roller_e_rim_front_left_link.STL" />
      </geometry>
    </collision>
  </link>
  <joint
    name="roller_e_rim_front_left_joint"
    type="continuous">
    <origin
      xyz="-0.027497 0.00039526 0.0045"
      rpy="1.5708 0 3.1272" />
    <parent
      link="rim_front_left_Link" />
    <child
      link="roller_e_rim_front_left_link" />
    <axis
      xyz="0 0 1" />
    <dynamics
      damping="0.01"
      friction="0.01" />
  </joint>
  <link
    name="roller_ne_rim_front_left_link">
    <inertial>
      <origin
        xyz="0 5.5511E-17 2.7756E-17"
        rpy="0 0 0" />
      <mass
        value="0.0066143" />
      <inertia
        ixx="0.0001"
        ixy="0.0"
        ixz="0.0"
        iyy="0.0001"
        iyz="0.0"
        izz="0.0002" />
    </inertial>
    <visual>
      <origin
        xyz="0 0 0"
        rpy="0 0 0" />
      <geometry>
        <mesh
          filename="package://car_4wd/meshes/roller_ne_rim_front_left_link.STL" />
      </geometry>
      <material
        name="">
        <color
          rgba="0.29804 0.29804 0.29804 1" />
      </material>
    </visual>
    <collision>
      <origin
        xyz="0 0 0"
        rpy="0 0 0" />
      <geometry>
        <mesh
          filename="package://car_4wd/meshes/roller_ne_rim_front_left_link.STL" />
      </geometry>
    </collision>
  </link>
  <joint
    name="roller_ne_rim_front_left_joint"
    type="continuous">
    <origin
      xyz="-0.019164 0.019723 0.0235"
      rpy="1.5708 0 2.3418" />
    <parent
      link="rim_front_left_Link" />
    <child
      link="roller_ne_rim_front_left_link" />
    <axis
      xyz="0 0 1" />
    <dynamics
      damping="0.01"
      friction="0.01" />
  </joint>
  <link
    name="roller_n_rim_front_left_link">
    <inertial>
      <origin
        xyz="0 0 0"
        rpy="0 0 0" />
      <mass
        value="0.0066143" />
      <inertia
        ixx="0.0001"
        ixy="0.0"
        ixz="0.0"
        iyy="0.0001"
        iyz="0.0"
        izz="0.0002" />
    </inertial>
    <visual>
      <origin
        xyz="0 0 0"
        rpy="0 0 0" />
      <geometry>
        <mesh
          filename="package://car_4wd/meshes/roller_n_rim_front_left_link.STL" />
      </geometry>
      <material
        name="">
        <color
          rgba="0.29804 0.29804 0.29804 1" />
      </material>
    </visual>
    <collision>
      <origin
        xyz="0 0 0"
        rpy="0 0 0" />
      <geometry>
        <mesh
          filename="package://car_4wd/meshes/roller_n_rim_front_left_link.STL" />
      </geometry>
    </collision>
  </link>
  <joint
    name="roller_n_rim_front_left_joint"
    type="continuous">
    <origin
      xyz="0.00039526 0.027497 0.0045"
      rpy="1.5708 0 1.5564" />
    <parent
      link="rim_front_left_Link" />
    <child
      link="roller_n_rim_front_left_link" />
    <axis
      xyz="0 0 1" />
    <dynamics
      damping="0.01"
      friction="0.01" />
  </joint>
  <link
    name="roller_nw_rim_front_left_link">
    <inertial>
      <origin
        xyz="0 0 0"
        rpy="0 0 0" />
      <mass
        value="0.0066143" />
      <inertia
        ixx="0.0001"
        ixy="0.0"
        ixz="0.0"
        iyy="0.0001"
        iyz="0.0"
        izz="0.0002" />
    </inertial>
    <visual>
      <origin
        xyz="0 0 0"
        rpy="0 0 0" />
      <geometry>
        <mesh
          filename="package://car_4wd/meshes/roller_nw_rim_front_left_link.STL" />
      </geometry>
      <material
        name="">
        <color
          rgba="0.29804 0.29804 0.29804 1" />
      </material>
    </visual>
    <collision>
      <origin
        xyz="0 0 0"
        rpy="0 0 0" />
      <geometry>
        <mesh
          filename="package://car_4wd/meshes/roller_nw_rim_front_left_link.STL" />
      </geometry>
    </collision>
  </link>
  <joint
    name="roller_nw_rim_front_left_joint"
    type="continuous">
    <origin
      xyz="0.019723 0.019164 0.0235"
      rpy="1.5708 0 0.77102" />
    <parent
      link="rim_front_left_Link" />
    <child
      link="roller_nw_rim_front_left_link" />
    <axis
      xyz="0 0 1" />
    <dynamics
      damping="0.01"
      friction="0.01" />
  </joint>
  <link
    name="roller_w_rim_front_left_link">
    <inertial>
      <origin
        xyz="2.7756E-17 5.5511E-17 0"
        rpy="0 0 0" />
      <mass
        value="0.0066143" />
      <inertia
        ixx="0.0001"
        ixy="0.0"
        ixz="0.0"
        iyy="0.0001"
        iyz="0.0"
        izz="0.0002" />
    </inertial>
    <visual>
      <origin
        xyz="0 0 0"
        rpy="0 0 0" />
      <geometry>
        <mesh
          filename="package://car_4wd/meshes/roller_w_rim_front_left_link.STL" />
      </geometry>
      <material
        name="">
        <color
          rgba="0.29804 0.29804 0.29804 1" />
      </material>
    </visual>
    <collision>
      <origin
        xyz="0 0 0"
        rpy="0 0 0" />
      <geometry>
        <mesh
          filename="package://car_4wd/meshes/roller_w_rim_front_left_link.STL" />
      </geometry>
    </collision>
  </link>
  <joint
    name="roller_w_rim_front_left_joint"
    type="continuous">
    <origin
      xyz="0.027497 -0.00039526 0.0045"
      rpy="1.5708 0 -0.014374" />
    <parent
      link="rim_front_left_Link" />
    <child
      link="roller_w_rim_front_left_link" />
    <axis
      xyz="0 0 1" />
    <dynamics
      damping="0.01"
      friction="0.01" />
  </joint>
  <link
    name="roller_sw_rim_front_left_link">
    <inertial>
      <origin
        xyz="0 0 0"
        rpy="0 0 0" />
      <mass
        value="0.0066143" />
      <inertia
        ixx="0.0001"
        ixy="0.0"
        ixz="0.0"
        iyy="0.0001"
        iyz="0.0"
        izz="0.0002" />
    </inertial>
    <visual>
      <origin
        xyz="0 0 0"
        rpy="0 0 0" />
      <geometry>
        <mesh
          filename="package://car_4wd/meshes/roller_sw_rim_front_left_link.STL" />
      </geometry>
      <material
        name="">
        <color
          rgba="0.29804 0.29804 0.29804 1" />
      </material>
    </visual>
    <collision>
      <origin
        xyz="0 0 0"
        rpy="0 0 0" />
      <geometry>
        <mesh
          filename="package://car_4wd/meshes/roller_sw_rim_front_left_link.STL" />
      </geometry>
    </collision>
  </link>
  <joint
    name="roller_sw_rim_front_left_joint"
    type="continuous">
    <origin
      xyz="0.019164 -0.019723 0.0235"
      rpy="1.5708 0 -0.79977" />
    <parent
      link="rim_front_left_Link" />
    <child
      link="roller_sw_rim_front_left_link" />
    <axis
      xyz="0 0 1" />
    <dynamics
      damping="0.01"
      friction="0.01" />
  </joint>
  <link
    name="roller_s_rim_front_left_link">
    <inertial>
      <origin
        xyz="0 0 0"
        rpy="0 0 0" />
      <mass
        value="0.0066143" />
      <inertia
        ixx="0.0001"
        ixy="0.0"
        ixz="0.0"
        iyy="0.0001"
        iyz="0.0"
        izz="0.0002" />
    </inertial>
    <visual>
      <origin
        xyz="0 0 0"
        rpy="0 0 0" />
      <geometry>
        <mesh
          filename="package://car_4wd/meshes/roller_s_rim_front_left_link.STL" />
      </geometry>
      <material
        name="">
        <color
          rgba="0.29804 0.29804 0.29804 1" />
      </material>
    </visual>
    <collision>
      <origin
        xyz="0 0 0"
        rpy="0 0 0" />
      <geometry>
        <mesh
          filename="package://car_4wd/meshes/roller_s_rim_front_left_link.STL" />
      </geometry>
    </collision>
  </link>
  <joint
    name="roller_s_rim_front_left_joint"
    type="continuous">
    <origin
      xyz="-0.00039526 -0.027497 0.0045"
      rpy="1.5708 0 -1.5852" />
    <parent
      link="rim_front_left_Link" />
    <child
      link="roller_s_rim_front_left_link" />
    <axis
      xyz="0 0 1" />
    <dynamics
      damping="0.01"
      friction="0.01" />
  </joint>
  <link
    name="roller_se_rim_front_left_link">
    <inertial>
      <origin
        xyz="1.3878E-17 0 1.3878E-17"
        rpy="0 0 0" />
      <mass
        value="0.0066143" />
      <inertia
        ixx="0.0001"
        ixy="0.0"
        ixz="0.0"
        iyy="0.0001"
        iyz="0.0"
        izz="0.0002" />
    </inertial>
    <visual>
      <origin
        xyz="0 0 0"
        rpy="0 0 0" />
      <geometry>
        <mesh
          filename="package://car_4wd/meshes/roller_se_rim_front_left_link.STL" />
      </geometry>
      <material
        name="">
        <color
          rgba="0.29804 0.29804 0.29804 1" />
      </material>
    </visual>
    <collision>
      <origin
        xyz="0 0 0"
        rpy="0 0 0" />
      <geometry>
        <mesh
          filename="package://car_4wd/meshes/roller_se_rim_front_left_link.STL" />
      </geometry>
    </collision>
  </link>
  <joint
    name="roller_se_rim_front_left_joint"
    type="continuous">
    <origin
      xyz="-0.019723 -0.019164 0.0235"
      rpy="1.5708 0 -2.3706" />
    <parent
      link="rim_front_left_Link" />
    <child
      link="roller_se_rim_front_left_link" />
    <axis
      xyz="0 0 1" />
    <dynamics
      damping="0.01"
      friction="0.01" />
  </joint>


  <link name="rim_front_right_Link">
    <inertial>
      <origin xyz="0 -1.1102E-16 0.013812" rpy="0 0 0" />
      <mass value="0.045828" />
      <inertia ixx="0.0001" ixy="0.0" ixz="0.0" iyy="0.0001" iyz="0.0" izz="0.0002" />
    </inertial>
    <visual>
      <origin xyz="0 0 0" rpy="0 0 0" />
      <geometry>
        <mesh filename="package://car_4wd/meshes/rim.STL" />
      </geometry>
      <material name="">
        <color rgba="0.79216 0.81961 0.93333 1" />
      </material>
    </visual>
    <collision>
      <origin xyz="0 0 0" rpy="0 0 0" />
      <geometry>
        <mesh filename="package://car_4wd/meshes/rim.STL" />
      </geometry>
    </collision>
  </link>
  <joint name="rim_front_right_joint" type="continuous">
    <origin xyz="0.11977 -0.12038 -0.0255"
      rpy="1.5708 0 -2.3562" />
    <parent link="base_link" />
    <child link="rim_front_right_Link" />
    <axis xyz="0 0 -1" />
    <dynamics damping="0.01" friction="0.01" />
  </joint>

  <link name="roller_e_rim_front_right_link">
    <inertial>
      <origin xyz="-2.7756E-17 0 0" rpy="0 0 0" />
      <mass value="0.0066143" />
      <inertia ixx="0.0001" ixy="0.0" ixz="0.0" iyy="0.0001" iyz="0.0" izz="0.0002" />
    </inertial>
    <visual>
      <origin xyz="0 0 0" rpy="0 0 0" />
      <geometry>
        <mesh filename="package://car_4wd/meshes/roller.STL" />
      </geometry>
      <material name="">
        <color rgba="0.29804 0.29804 0.29804 1" />
      </material>
    </visual>
    <collision>
      <origin xyz="0 0 0" rpy="0 0 0" />
      <geometry>
        <mesh filename="package://car_4wd/meshes/roller.STL" />
      </geometry>
    </collision>
  </link>
  <joint name="roller_e_rim_front_right_joint" type="continuous">
    <origin xyz="-0.027497 0.00039526 0.0045" rpy="1.5708 0 3.1272" />
    <parent link="rim_front_right_Link" />
    <child link="roller_e_rim_front_right_link" />
    <axis xyz="0 0 1" />
    <dynamics damping="0.01" friction="0.01" />
  </joint>
  <link name="roller_ne_rim_front_right_link">
    <inertial>
      <origin xyz="0 5.5511E-17 2.7756E-17" rpy="0 0 0" />
      <mass value="0.0066143" />
      <inertia ixx="0.0001" ixy="0.0" ixz="0.0" iyy="0.0001" iyz="0.0" izz="0.0002" />
    </inertial>
    <visual>
      <origin xyz="0 0 0" rpy="0 0 0" />
      <geometry>
        <mesh filename="package://car_4wd/meshes/roller.STL" />
      </geometry>
      <material name="">
        <color rgba="0.29804 0.29804 0.29804 1" />
      </material>
    </visual>
    <collision>
      <origin xyz="0 0 0" rpy="0 0 0" />
      <geometry>
        <mesh filename="package://car_4wd/meshes/roller.STL" />
      </geometry>
    </collision>
  </link>
  <joint name="roller_ne_rim_front_right_joint" type="continuous">
    <origin xyz="-0.019164 0.019723 0.0235" rpy="1.5708 0 2.3418" />
    <parent link="rim_front_right_Link" />
    <child link="roller_ne_rim_front_right_link" />
    <axis xyz="0 0 1" />
    <dynamics damping="0.01" friction="0.01" />
  </joint>
  <link name="roller_n_rim_front_right_link">
    <inertial>
      <origin xyz="0 0 0" rpy="0 0 0" />
      <mass value="0.0066143" />
      <inertia ixx="0.0001" ixy="0.0" ixz="0.0" iyy="0.0001" iyz="0.0" izz="0.0002" />
    </inertial>
    <visual>
      <origin xyz="0 0 0" rpy="0 0 0" />
      <geometry>
        <mesh filename="package://car_4wd/meshes/roller.STL" />
      </geometry>
      <material name="">
        <color rgba="0.29804 0.29804 0.29804 1" />
      </material>
    </visual>
    <collision>
      <origin xyz="0 0 0" rpy="0 0 0" />
      <geometry>
        <mesh filename="package://car_4wd/meshes/roller.STL" />
      </geometry>
    </collision>
  </link>
  <joint name="roller_n_rim_front_right_joint" type="continuous">
    <origin xyz="0.00039526 0.027497 0.0045" rpy="1.5708 0 1.5564" />
    <parent link="rim_front_right_Link" />
    <child link="roller_n_rim_front_right_link" />
    <axis xyz="0 0 1" />
    <dynamics damping="0.01" friction="0.01" />
  </joint>
  <link name="roller_nw_rim_front_right_link">
    <inertial>
      <origin xyz="0 0 0" rpy="0 0 0" />
      <mass value="0.0066143" />
      <inertia ixx="0.0001" ixy="0.0" ixz="0.0" iyy="0.0001" iyz="0.0" izz="0.0002" />
    </inertial>
    <visual>
      <origin xyz="0 0 0" rpy="0 0 0" />
      <geometry>
        <mesh filename="package://car_4wd/meshes/roller.STL" />
      </geometry>
      <material name="">
        <color rgba="0.29804 0.29804 0.29804 1" />
      </material>
    </visual>
    <collision>
      <origin xyz="0 0 0" rpy="0 0 0" />
      <geometry>
        <mesh filename="package://car_4wd/meshes/roller.STL" />
      </geometry>
    </collision>
  </link>
  <joint name="roller_nw_rim_front_right_joint" type="continuous">
    <origin xyz="0.019723 0.019164 0.0235" rpy="1.5708 0 0.77102" />
    <parent link="rim_front_right_Link" />
    <child link="roller_nw_rim_front_right_link" />
    <axis xyz="0 0 1" />
    <dynamics damping="0.01" friction="0.01" />
  </joint>
  <link name="roller_w_rim_front_right_link">
    <inertial>
      <origin xyz="2.7756E-17 5.5511E-17 0" rpy="0 0 0" />
      <mass value="0.0066143" />
      <inertia ixx="0.0001" ixy="0.0" ixz="0.0" iyy="0.0001" iyz="0.0" izz="0.0002" />
    </inertial>
    <visual>
      <origin xyz="0 0 0" rpy="0 0 0" />
      <geometry>
        <mesh filename="package://car_4wd/meshes/roller.STL" />
      </geometry>
      <material name="">
        <color rgba="0.29804 0.29804 0.29804 1" />
      </material>
    </visual>
    <collision>
      <origin xyz="0 0 0" rpy="0 0 0" />
      <geometry>
        <mesh filename="package://car_4wd/meshes/roller.STL" />
      </geometry>
    </collision>
  </link>
  <joint name="roller_w_rim_front_right_joint" type="continuous">
    <origin xyz="0.027497 -0.00039526 0.0045" rpy="1.5708 0 -0.014374" />
    <parent link="rim_front_right_Link" />
    <child link="roller_w_rim_front_right_link" />
    <axis xyz="0 0 1" />
    <dynamics damping="0.01" friction="0.01" />
  </joint>
  <link name="roller_sw_rim_front_right_link">
    <inertial>
      <origin xyz="0 0 0" rpy="0 0 0" />
      <mass value="0.0066143" />
      <inertia ixx="0.0001" ixy="0.0" ixz="0.0" iyy="0.0001" iyz="0.0" izz="0.0002" />
    </inertial>
    <visual>
      <origin xyz="0 0 0" rpy="0 0 0" />
      <geometry>
        <mesh filename="package://car_4wd/meshes/roller.STL" />
      </geometry>
      <material name="">
        <color rgba="0.29804 0.29804 0.29804 1" />
      </material>
    </visual>
    <collision>
      <origin xyz="0 0 0" rpy="0 0 0" />
      <geometry>
        <mesh filename="package://car_4wd/meshes/roller.STL" />
      </geometry>
    </collision>
  </link>
  <joint name="roller_sw_rim_front_right_joint" type="continuous">
    <origin xyz="0.019164 -0.019723 0.0235" rpy="1.5708 0 -0.79977" />
    <parent link="rim_front_right_Link" />
    <child link="roller_sw_rim_front_right_link" />
    <axis xyz="0 0 1" />
    <dynamics damping="0.01" friction="0.01" />
  </joint>
  <link name="roller_s_rim_front_right_link">
    <inertial>
      <origin xyz="0 0 0" rpy="0 0 0" />
      <mass value="0.0066143" />
      <inertia ixx="0.0001" ixy="0.0" ixz="0.0" iyy="0.0001" iyz="0.0" izz="0.0002" />
    </inertial>
    <visual>
      <origin xyz="0 0 0" rpy="0 0 0" />
      <geometry>
        <mesh filename="package://car_4wd/meshes/roller.STL" />
      </geometry>
      <material name="">
        <color rgba="0.29804 0.29804 0.29804 1" />
      </material>
    </visual>
    <collision>
      <origin xyz="0 0 0" rpy="0 0 0" />
      <geometry>
        <mesh filename="package://car_4wd/meshes/roller.STL" />
      </geometry>
    </collision>
  </link>
  <joint name="roller_s_rim_front_right_joint" type="continuous">
    <origin xyz="-0.00039526 -0.027497 0.0045" rpy="1.5708 0 -1.5852" />
    <parent link="rim_front_right_Link" />
    <child link="roller_s_rim_front_right_link" />
    <axis xyz="0 0 1" />
    <dynamics damping="0.01" friction="0.01" />
  </joint>
  <link name="roller_se_rim_front_right_link">
    <inertial>
      <origin xyz="1.3878E-17 0 1.3878E-17" rpy="0 0 0" />
      <mass value="0.0066143" />
      <inertia ixx="0.0001" ixy="0.0" ixz="0.0" iyy="0.0001" iyz="0.0" izz="0.0002" />
    </inertial>
    <visual>
      <origin xyz="0 0 0" rpy="0 0 0" />
      <geometry>
        <mesh filename="package://car_4wd/meshes/roller.STL" />
      </geometry>
      <material name="">
        <color rgba="0.29804 0.29804 0.29804 1" />
      </material>
    </visual>
    <collision>
      <origin xyz="0 0 0" rpy="0 0 0" />
      <geometry>
        <mesh filename="package://car_4wd/meshes/roller.STL" />
      </geometry>
    </collision>
  </link>
  <joint name="roller_se_rim_front_right_joint" type="continuous">
    <origin xyz="-0.019723 -0.019164 0.0235" rpy="1.5708 0 -2.3706" />
    <parent link="rim_front_right_Link" />
    <child link="roller_se_rim_front_right_link" />
    <axis xyz="0 0 1" />
    <dynamics damping="0.01" friction="0.01" />
  </joint>


  <link name="rim_rear_left_Link">
    <inertial>
      <origin xyz="0 -1.1102E-16 0.013812" rpy="0 0 0" />
      <mass value="0.045828" />
      <inertia ixx="0.0001" ixy="0.0" ixz="0.0" iyy="0.0001" iyz="0.0" izz="0.0002" />
    </inertial>
    <visual>
      <origin xyz="0 0 0" rpy="0 0 0" />
      <geometry>
        <mesh filename="package://car_4wd/meshes/rim.STL" />
      </geometry>
      <material name="">
        <color rgba="0.79216 0.81961 0.93333 1" />
      </material>
    </visual>
    <collision>
      <origin xyz="0 0 0" rpy="0 0 0" />
      <geometry>
        <mesh filename="package://car_4wd/meshes/rim.STL" />
      </geometry>
    </collision>
  </link>
  <joint name="rim_rear_left_joint" type="continuous">
    <origin xyz="-0.11977 0.12038 -0.0255"
      rpy="1.5708 0 0.7854" />
    <parent link="base_link" />
    <child link="rim_rear_left_Link" />
    <axis xyz="0 0 -1" />
    <dynamics damping="0.01" friction="0.01" />
  </joint>

  <link name="roller_e_rim_rear_left_link">
    <inertial>
      <origin xyz="-2.7756E-17 0 0" rpy="0 0 0" />
      <mass value="0.0066143" />
      <inertia ixx="0.0001" ixy="0.0" ixz="0.0" iyy="0.0001" iyz="0.0" izz="0.0002" />
    </inertial>
    <visual>
      <origin xyz="0 0 0" rpy="0 0 0" />
      <geometry>
        <mesh filename="package://car_4wd/meshes/roller.STL" />
      </geometry>
      <material name="">
        <color rgba="0.29804 0.29804 0.29804 1" />
      </material>
    </visual>
    <collision>
      <origin xyz="0 0 0" rpy="0 0 0" />
      <geometry>
        <mesh filename="package://car_4wd/meshes/roller.STL" />
      </geometry>
    </collision>
  </link>
  <joint name="roller_e_rim_rear_left_joint" type="continuous">
    <origin xyz="-0.027497 0.00039526 0.0045" rpy="1.5708 0 3.1272" />
    <parent link="rim_rear_left_Link" />
    <child link="roller_e_rim_rear_left_link" />
    <axis xyz="0 0 1" />
    <dynamics damping="0.01" friction="0.01" />
  </joint>
  <link name="roller_ne_rim_rear_left_link">
    <inertial>
      <origin xyz="0 5.5511E-17 2.7756E-17" rpy="0 0 0" />
      <mass value="0.0066143" />
      <inertia ixx="0.0001" ixy="0.0" ixz="0.0" iyy="0.0001" iyz="0.0" izz="0.0002" />
    </inertial>
    <visual>
      <origin xyz="0 0 0" rpy="0 0 0" />
      <geometry>
        <mesh filename="package://car_4wd/meshes/roller.STL" />
      </geometry>
      <material name="">
        <color rgba="0.29804 0.29804 0.29804 1" />
      </material>
    </visual>
    <collision>
      <origin xyz="0 0 0" rpy="0 0 0" />
      <geometry>
        <mesh filename="package://car_4wd/meshes/roller.STL" />
      </geometry>
    </collision>
  </link>
  <joint name="roller_ne_rim_rear_left_joint" type="continuous">
    <origin xyz="-0.019164 0.019723 0.0235" rpy="1.5708 0 2.3418" />
    <parent link="rim_rear_left_Link" />
    <child link="roller_ne_rim_rear_left_link" />
    <axis xyz="0 0 1" />
    <dynamics damping="0.01" friction="0.01" />
  </joint>
  <link name="roller_n_rim_rear_left_link">
    <inertial>
      <origin xyz="0 0 0" rpy="0 0 0" />
      <mass value="0.0066143" />
      <inertia ixx="0.0001" ixy="0.0" ixz="0.0" iyy="0.0001" iyz="0.0" izz="0.0002" />
    </inertial>
    <visual>
      <origin xyz="0 0 0" rpy="0 0 0" />
      <geometry>
        <mesh filename="package://car_4wd/meshes/roller.STL" />
      </geometry>
      <material name="">
        <color rgba="0.29804 0.29804 0.29804 1" />
      </material>
    </visual>
    <collision>
      <origin xyz="0 0 0" rpy="0 0 0" />
      <geometry>
        <mesh filename="package://car_4wd/meshes/roller.STL" />
      </geometry>
    </collision>
  </link>
  <joint name="roller_n_rim_rear_left_joint" type="continuous">
    <origin xyz="0.00039526 0.027497 0.0045" rpy="1.5708 0 1.5564" />
    <parent link="rim_rear_left_Link" />
    <child link="roller_n_rim_rear_left_link" />
    <axis xyz="0 0 1" />
    <dynamics damping="0.01" friction="0.01" />
  </joint>
  <link name="roller_nw_rim_rear_left_link">
    <inertial>
      <origin xyz="0 0 0" rpy="0 0 0" />
      <mass value="0.0066143" />
      <inertia ixx="0.0001" ixy="0.0" ixz="0.0" iyy="0.0001" iyz="0.0" izz="0.0002" />
    </inertial>
    <visual>
      <origin xyz="0 0 0" rpy="0 0 0" />
      <geometry>
        <mesh filename="package://car_4wd/meshes/roller.STL" />
      </geometry>
      <material name="">
        <color rgba="0.29804 0.29804 0.29804 1" />
      </material>
    </visual>
    <collision>
      <origin xyz="0 0 0" rpy="0 0 0" />
      <geometry>
        <mesh filename="package://car_4wd/meshes/roller.STL" />
      </geometry>
    </collision>
  </link>
  <joint name="roller_nw_rim_rear_left_joint" type="continuous">
    <origin xyz="0.019723 0.019164 0.0235" rpy="1.5708 0 0.77102" />
    <parent link="rim_rear_left_Link" />
    <child link="roller_nw_rim_rear_left_link" />
    <axis xyz="0 0 1" />
    <dynamics damping="0.01" friction="0.01" />
  </joint>
  <link name="roller_w_rim_rear_left_link">
    <inertial>
      <origin xyz="2.7756E-17 5.5511E-17 0" rpy="0 0 0" />
      <mass value="0.0066143" />
      <inertia ixx="0.0001" ixy="0.0" ixz="0.0" iyy="0.0001" iyz="0.0" izz="0.0002" />
    </inertial>
    <visual>
      <origin xyz="0 0 0" rpy="0 0 0" />
      <geometry>
        <mesh filename="package://car_4wd/meshes/roller.STL" />
      </geometry>
      <material name="">
        <color rgba="0.29804 0.29804 0.29804 1" />
      </material>
    </visual>
    <collision>
      <origin xyz="0 0 0" rpy="0 0 0" />
      <geometry>
        <mesh filename="package://car_4wd/meshes/roller.STL" />
      </geometry>
    </collision>
  </link>
  <joint name="roller_w_rim_rear_left_joint" type="continuous">
    <origin xyz="0.027497 -0.00039526 0.0045" rpy="1.5708 0 -0.014374" />
    <parent link="rim_rear_left_Link" />
    <child link="roller_w_rim_rear_left_link" />
    <axis xyz="0 0 1" />
    <dynamics damping="0.01" friction="0.01" />
  </joint>
  <link name="roller_sw_rim_rear_left_link">
    <inertial>
      <origin xyz="0 0 0" rpy="0 0 0" />
      <mass value="0.0066143" />
      <inertia ixx="0.0001" ixy="0.0" ixz="0.0" iyy="0.0001" iyz="0.0" izz="0.0002" />
    </inertial>
    <visual>
      <origin xyz="0 0 0" rpy="0 0 0" />
      <geometry>
        <mesh filename="package://car_4wd/meshes/roller.STL" />
      </geometry>
      <material name="">
        <color rgba="0.29804 0.29804 0.29804 1" />
      </material>
    </visual>
    <collision>
      <origin xyz="0 0 0" rpy="0 0 0" />
      <geometry>
        <mesh filename="package://car_4wd/meshes/roller.STL" />
      </geometry>
    </collision>
  </link>
  <joint name="roller_sw_rim_rear_left_joint" type="continuous">
    <origin xyz="0.019164 -0.019723 0.0235" rpy="1.5708 0 -0.79977" />
    <parent link="rim_rear_left_Link" />
    <child link="roller_sw_rim_rear_left_link" />
    <axis xyz="0 0 1" />
    <dynamics damping="0.01" friction="0.01" />
  </joint>
  <link name="roller_s_rim_rear_left_link">
    <inertial>
      <origin xyz="0 0 0" rpy="0 0 0" />
      <mass value="0.0066143" />
      <inertia ixx="0.0001" ixy="0.0" ixz="0.0" iyy="0.0001" iyz="0.0" izz="0.0002" />
    </inertial>
    <visual>
      <origin xyz="0 0 0" rpy="0 0 0" />
      <geometry>
        <mesh filename="package://car_4wd/meshes/roller.STL" />
      </geometry>
      <material name="">
        <color rgba="0.29804 0.29804 0.29804 1" />
      </material>
    </visual>
    <collision>
      <origin xyz="0 0 0" rpy="0 0 0" />
      <geometry>
        <mesh filename="package://car_4wd/meshes/roller.STL" />
      </geometry>
    </collision>
  </link>
  <joint name="roller_s_rim_rear_left_joint" type="continuous">
    <origin xyz="-0.00039526 -0.027497 0.0045" rpy="1.5708 0 -1.5852" />
    <parent link="rim_rear_left_Link" />
    <child link="roller_s_rim_rear_left_link" />
    <axis xyz="0 0 1" />
    <dynamics damping="0.01" friction="0.01" />
  </joint>
  <link name="roller_se_rim_rear_left_link">
    <inertial>
      <origin xyz="1.3878E-17 0 1.3878E-17" rpy="0 0 0" />
      <mass value="0.0066143" />
      <inertia ixx="0.0001" ixy="0.0" ixz="0.0" iyy="0.0001" iyz="0.0" izz="0.0002" />
    </inertial>
    <visual>
      <origin xyz="0 0 0" rpy="0 0 0" />
      <geometry>
        <mesh filename="package://car_4wd/meshes/roller.STL" />
      </geometry>
      <material name="">
        <color rgba="0.29804 0.29804 0.29804 1" />
      </material>
    </visual>
    <collision>
      <origin xyz="0 0 0" rpy="0 0 0" />
      <geometry>
        <mesh filename="package://car_4wd/meshes/roller.STL" />
      </geometry>
    </collision>
  </link>
  <joint name="roller_se_rim_rear_left_joint" type="continuous">
    <origin xyz="-0.019723 -0.019164 0.0235" rpy="1.5708 0 -2.3706" />
    <parent link="rim_rear_left_Link" />
    <child link="roller_se_rim_rear_left_link" />
    <axis xyz="0 0 1" />
    <dynamics damping="0.01" friction="0.01" />
  </joint>


  <link name="rim_rear_right_Link">
    <inertial>
      <origin xyz="0 -1.1102E-16 0.013812" rpy="0 0 0" />
      <mass value="0.045828" />
      <inertia ixx="0.0001" ixy="0.0" ixz="0.0" iyy="0.0001" iyz="0.0" izz="0.0002" />
    </inertial>
    <visual>
      <origin xyz="0 0 0" rpy="0 0 0" />
      <geometry>
        <mesh filename="package://car_4wd/meshes/rim.STL" />
      </geometry>
      <material name="">
        <color rgba="0.79216 0.81961 0.93333 1" />
      </material>
    </visual>
    <collision>
      <origin xyz="0 0 0" rpy="0 0 0" />
      <geometry>
        <mesh filename="package://car_4wd/meshes/rim.STL" />
      </geometry>
    </collision>
  </link>
  <joint name="rim_rear_right_joint" type="continuous">
    <origin xyz="-0.11977 -0.12038 -0.0255"
      rpy="1.5708 0 -3.927" />
    <parent link="base_link" />
    <child link="rim_rear_right_Link" />
    <axis xyz="0 0 -1" />
    <dynamics damping="0.01" friction="0.01" />
  </joint>

  <link name="roller_e_rim_rear_right_link">
    <inertial>
      <origin xyz="-2.7756E-17 0 0" rpy="0 0 0" />
      <mass value="0.0066143" />
      <inertia ixx="0.0001" ixy="0.0" ixz="0.0" iyy="0.0001" iyz="0.0" izz="0.0002" />
    </inertial>
    <visual>
      <origin xyz="0 0 0" rpy="0 0 0" />
      <geometry>
        <mesh filename="package://car_4wd/meshes/roller.STL" />
      </geometry>
      <material name="">
        <color rgba="0.29804 0.29804 0.29804 1" />
      </material>
    </visual>
    <collision>
      <origin xyz="0 0 0" rpy="0 0 0" />
      <geometry>
        <mesh filename="package://car_4wd/meshes/roller.STL" />
      </geometry>
    </collision>
  </link>
  <joint name="roller_e_rim_rear_right_joint" type="continuous">
    <origin xyz="-0.027497 0.00039526 0.0045" rpy="1.5708 0 3.1272" />
    <parent link="rim_rear_right_Link" />
    <child link="roller_e_rim_rear_right_link" />
    <axis xyz="0 0 1" />
    <dynamics damping="0.01" friction="0.01" />
  </joint>
  <link name="roller_ne_rim_rear_right_link">
    <inertial>
      <origin xyz="0 5.5511E-17 2.7756E-17" rpy="0 0 0" />
      <mass value="0.0066143" />
      <inertia ixx="0.0001" ixy="0.0" ixz="0.0" iyy="0.0001" iyz="0.0" izz="0.0002" />
    </inertial>
    <visual>
      <origin xyz="0 0 0" rpy="0 0 0" />
      <geometry>
        <mesh filename="package://car_4wd/meshes/roller.STL" />
      </geometry>
      <material name="">
        <color rgba="0.29804 0.29804 0.29804 1" />
      </material>
    </visual>
    <collision>
      <origin xyz="0 0 0" rpy="0 0 0" />
      <geometry>
        <mesh filename="package://car_4wd/meshes/roller.STL" />
      </geometry>
    </collision>
  </link>
  <joint name="roller_ne_rim_rear_right_joint" type="continuous">
    <origin xyz="-0.019164 0.019723 0.0235" rpy="1.5708 0 2.3418" />
    <parent link="rim_rear_right_Link" />
    <child link="roller_ne_rim_rear_right_link" />
    <axis xyz="0 0 1" />
    <dynamics damping="0.01" friction="0.01" />
  </joint>
  <link name="roller_n_rim_rear_right_link">
    <inertial>
      <origin xyz="0 0 0" rpy="0 0 0" />
      <mass value="0.0066143" />
      <inertia ixx="0.0001" ixy="0.0" ixz="0.0" iyy="0.0001" iyz="0.0" izz="0.0002" />
    </inertial>
    <visual>
      <origin xyz="0 0 0" rpy="0 0 0" />
      <geometry>
        <mesh filename="package://car_4wd/meshes/roller.STL" />
      </geometry>
      <material name="">
        <color rgba="0.29804 0.29804 0.29804 1" />
      </material>
    </visual>
    <collision>
      <origin xyz="0 0 0" rpy="0 0 0" />
      <geometry>
        <mesh filename="package://car_4wd/meshes/roller.STL" />
      </geometry>
    </collision>
  </link>
  <joint name="roller_n_rim_rear_right_joint" type="continuous">
    <origin xyz="0.00039526 0.027497 0.0045" rpy="1.5708 0 1.5564" />
    <parent link="rim_rear_right_Link" />
    <child link="roller_n_rim_rear_right_link" />
    <axis xyz="0 0 1" />
    <dynamics damping="0.01" friction="0.01" />
  </joint>
  <link name="roller_nw_rim_rear_right_link">
    <inertial>
      <origin xyz="0 0 0" rpy="0 0 0" />
      <mass value="0.0066143" />
      <inertia ixx="0.0001" ixy="0.0" ixz="0.0" iyy="0.0001" iyz="0.0" izz="0.0002" />
    </inertial>
    <visual>
      <origin xyz="0 0 0" rpy="0 0 0" />
      <geometry>
        <mesh filename="package://car_4wd/meshes/roller.STL" />
      </geometry>
      <material name="">
        <color rgba="0.29804 0.29804 0.29804 1" />
      </material>
    </visual>
    <collision>
      <origin xyz="0 0 0" rpy="0 0 0" />
      <geometry>
        <mesh filename="package://car_4wd/meshes/roller.STL" />
      </geometry>
    </collision>
  </link>
  <joint name="roller_nw_rim_rear_right_joint" type="continuous">
    <origin xyz="0.019723 0.019164 0.0235" rpy="1.5708 0 0.77102" />
    <parent link="rim_rear_right_Link" />
    <child link="roller_nw_rim_rear_right_link" />
    <axis xyz="0 0 1" />
    <dynamics damping="0.01" friction="0.01" />
  </joint>
  <link name="roller_w_rim_rear_right_link">
    <inertial>
      <origin xyz="2.7756E-17 5.5511E-17 0" rpy="0 0 0" />
      <mass value="0.0066143" />
      <inertia ixx="0.0001" ixy="0.0" ixz="0.0" iyy="0.0001" iyz="0.0" izz="0.0002" />
    </inertial>
    <visual>
      <origin xyz="0 0 0" rpy="0 0 0" />
      <geometry>
        <mesh filename="package://car_4wd/meshes/roller.STL" />
      </geometry>
      <material name="">
        <color rgba="0.29804 0.29804 0.29804 1" />
      </material>
    </visual>
    <collision>
      <origin xyz="0 0 0" rpy="0 0 0" />
      <geometry>
        <mesh filename="package://car_4wd/meshes/roller.STL" />
      </geometry>
    </collision>
  </link>
  <joint name="roller_w_rim_rear_right_joint" type="continuous">
    <origin xyz="0.027497 -0.00039526 0.0045" rpy="1.5708 0 -0.014374" />
    <parent link="rim_rear_right_Link" />
    <child link="roller_w_rim_rear_right_link" />
    <axis xyz="0 0 1" />
    <dynamics damping="0.01" friction="0.01" />
  </joint>
  <link name="roller_sw_rim_rear_right_link">
    <inertial>
      <origin xyz="0 0 0" rpy="0 0 0" />
      <mass value="0.0066143" />
      <inertia ixx="0.0001" ixy="0.0" ixz="0.0" iyy="0.0001" iyz="0.0" izz="0.0002" />
    </inertial>
    <visual>
      <origin xyz="0 0 0" rpy="0 0 0" />
      <geometry>
        <mesh filename="package://car_4wd/meshes/roller.STL" />
      </geometry>
      <material name="">
        <color rgba="0.29804 0.29804 0.29804 1" />
      </material>
    </visual>
    <collision>
      <origin xyz="0 0 0" rpy="0 0 0" />
      <geometry>
        <mesh filename="package://car_4wd/meshes/roller.STL" />
      </geometry>
    </collision>
  </link>
  <joint name="roller_sw_rim_rear_right_joint" type="continuous">
    <origin xyz="0.019164 -0.019723 0.0235" rpy="1.5708 0 -0.79977" />
    <parent link="rim_rear_right_Link" />
    <child link="roller_sw_rim_rear_right_link" />
    <axis xyz="0 0 1" />
    <dynamics damping="0.01" friction="0.01" />
  </joint>
  <link name="roller_s_rim_rear_right_link">
    <inertial>
      <origin xyz="0 0 0" rpy="0 0 0" />
      <mass value="0.0066143" />
      <inertia ixx="0.0001" ixy="0.0" ixz="0.0" iyy="0.0001" iyz="0.0" izz="0.0002" />
    </inertial>
    <visual>
      <origin xyz="0 0 0" rpy="0 0 0" />
      <geometry>
        <mesh filename="package://car_4wd/meshes/roller.STL" />
      </geometry>
      <material name="">
        <color rgba="0.29804 0.29804 0.29804 1" />
      </material>
    </visual>
    <collision>
      <origin xyz="0 0 0" rpy="0 0 0" />
      <geometry>
        <mesh filename="package://car_4wd/meshes/roller.STL" />
      </geometry>
    </collision>
  </link>
  <joint name="roller_s_rim_rear_right_joint" type="continuous">
    <origin xyz="-0.00039526 -0.027497 0.0045" rpy="1.5708 0 -1.5852" />
    <parent link="rim_rear_right_Link" />
    <child link="roller_s_rim_rear_right_link" />
    <axis xyz="0 0 1" />
    <dynamics damping="0.01" friction="0.01" />
  </joint>
  <link name="roller_se_rim_rear_right_link">
    <inertial>
      <origin xyz="1.3878E-17 0 1.3878E-17" rpy="0 0 0" />
      <mass value="0.0066143" />
      <inertia ixx="0.0001" ixy="0.0" ixz="0.0" iyy="0.0001" iyz="0.0" izz="0.0002" />
    </inertial>
    <visual>
      <origin xyz="0 0 0" rpy="0 0 0" />
      <geometry>
        <mesh filename="package://car_4wd/meshes/roller.STL" />
      </geometry>
      <material name="">
        <color rgba="0.29804 0.29804 0.29804 1" />
      </material>
    </visual>
    <collision>
      <origin xyz="0 0 0" rpy="0 0 0" />
      <geometry>
        <mesh filename="package://car_4wd/meshes/roller.STL" />
      </geometry>
    </collision>
  </link>
  <joint name="roller_se_rim_rear_right_joint" type="continuous">
    <origin xyz="-0.019723 -0.019164 0.0235" rpy="1.5708 0 -2.3706" />
    <parent link="rim_rear_right_Link" />
    <child link="roller_se_rim_rear_right_link" />
    <axis xyz="0 0 1" />
    <dynamics damping="0.01" friction="0.01" />
  </joint>

  <link
    name="lidar_Link">
    <inertial>
      <origin
        xyz="0.0082941 0 -0.0085489"
        rpy="0 0 0" />
      <mass
        value="0.1467" />
      <inertia
        ixx="6.2272E-05"
        ixy="-1.6091E-20"
        ixz="1.8866E-05"
        iyy="0.00010967"
        iyz="9.8493E-21"
        izz="0.00012568" />
    </inertial>
    <visual>
      <origin
        xyz="0 0 0"
        rpy="0 0 0" />
      <geometry>
        <mesh
          filename="package://car_4wd/meshes/lidar_Link.STL" />
      </geometry>
      <material
        name="">
        <color
          rgba="0.79216 0.81961 0.93333 1" />
      </material>
    </visual>
    <collision>
      <origin
        xyz="0 0 0"
        rpy="0 0 0" />
      <geometry>
        <mesh
          filename="package://car_4wd/meshes/lidar_Link.STL" />
      </geometry>
    </collision>
  </link>
  <joint
    name="lidar_joint"
    type="fixed">
    <origin
      xyz="-0.0071105 0 0.04625"
      rpy="0 0 0" />
    <parent
      link="base_link" />
    <child
      link="lidar_Link" />
    <axis
      xyz="0 0 0" />
    <dynamics
      damping="0.01"
      friction="0.01" />
  </joint>
  <link
    name="cam_Link">
    <inertial>
      <origin
        xyz="-0.011444 -0.001705 -0.0001361"
        rpy="0 0 0" />
      <mass
        value="0.10791" />
      <inertia
        ixx="7.1255E-05"
        ixy="-1.7837E-08"
        ixz="4.9293E-08"
        iyy="7.71E-06"
        iyz="2.2103E-10"
        izz="7.0257E-05" />
    </inertial>
    <visual>
      <origin
        xyz="0 0 0"
        rpy="0 0 0" />
      <geometry>
        <mesh
          filename="package://car_4wd/meshes/cam_Link.STL" />
      </geometry>
      <material
        name="">
        <color
          rgba="0.89804 0.91765 0.92941 1" />
      </material>
    </visual>
    <collision>
      <origin
        xyz="0 0 0"
        rpy="0 0 0" />
      <geometry>
        <mesh
          filename="package://car_4wd/meshes/cam_Link.STL" />
      </geometry>
    </collision>
  </link>
  <joint
    name="cam_joint"
    type="fixed">
    <origin
      xyz="0.11939 0.0017162 0.089"
      rpy="0 0 0" />
    <parent
      link="base_link" />
    <child
      link="cam_Link" />
    <axis
      xyz="0 0 0" />
    <dynamics
      damping="0.01"
      friction="0.01" />
  </joint>
  <link
    name="gps_Link">
    <inertial>
      <origin
        xyz="-0.000234344503684682 -0.000480179325965335 -0.0080940119068153"
        rpy="0 0 0" />
      <mass
        value="0.0273352261247105" />
      <inertia
        ixx="3.55571582981261E-06"
        ixy="-1.49360731623014E-08"
        ixz="1.01926750378263E-08"
        iyy="3.68244652590976E-06"
        iyz="-5.55452543457984E-10"
        izz="7.06140819525252E-06" />
    </inertial>
    <visual>
      <origin
        xyz="0 0 0"
        rpy="0 0 0" />
      <geometry>
        <mesh
          filename="package://car_4wd/meshes/gps_Link.STL" />
      </geometry>
      <material
        name="">
        <color
          rgba="0.752941176470588 0.752941176470588 0.752941176470588 1" />
      </material>
    </visual>
    <collision>
      <origin
        xyz="0 0 0"
        rpy="0 0 0" />
      <geometry>
        <mesh
          filename="package://car_4wd/meshes/gps_Link.STL" />
      </geometry>
    </collision>
  </link>
  <joint
    name="gps_joint"
    type="fixed">
    <origin
      xyz="-0.10189 0.00012301 0.028139"
      rpy="0 0 0" />
    <parent
      link="base_link" />
    <child
      link="gps_Link" />
    <axis
      xyz="0 0 0" />
    <dynamics
      damping="0.01"
      friction="0.01" />
  </joint>
  <link
    name="de_Link">
    <inertial>
      <origin
        xyz="0 0 0"
        rpy="0 0 0" />
      <mass
        value="0" />
      <inertia
        ixx="0"
        ixy="0"
        ixz="0"
        iyy="0"
        iyz="0"
        izz="0" />
    </inertial>
    <visual>
      <origin
        xyz="0 0 0"
        rpy="0 0 0" />
      <geometry>
        <mesh
          filename="package://car_4wd/meshes/de_Link.STL" />
      </geometry>
      <material
        name="">
        <color
          rgba="1 1 1 1" />
      </material>
    </visual>
    <collision>
      <origin
        xyz="0 0 0"
        rpy="0 0 0" />
      <geometry>
        <mesh
          filename="package://car_4wd/meshes/de_Link.STL" />
      </geometry>
    </collision>
  </link>
  <joint
    name="de_joint"
    type="fixed">
    <origin
      xyz="-0.00061051 0 0.104"
      rpy="0 0 0" />
    <parent
      link="base_link" />
    <child
      link="de_Link" />
    <axis
      xyz="0 0 0" />
    <dynamics
      damping="0.01"
      friction="0.01" />
  </joint>
  <link
    name="1_Link">
    <inertial>
      <origin
        xyz="0.002182 0.0093368 0.020798"
        rpy="0 0 0" />
      <mass
        value="0.09842" />
      <inertia
        ixx="6.5924E-05"
        ixy="-1.4202E-06"
        ixz="6.6287E-08"
        iyy="6.0179E-05"
        iyz="2.8365E-07"
        izz="5.423E-05" />
    </inertial>
    <visual>
      <origin
        xyz="0 0 0"
        rpy="0 0 0" />
      <geometry>
        <mesh
          filename="package://car_4wd/meshes/1_Link.STL" />
      </geometry>
      <material
        name="">
        <color
          rgba="0.79216 0.81961 0.93333 1" />
      </material>
    </visual>
    <collision>
      <origin
        xyz="0 0 0"
        rpy="0 0 0" />
      <geometry>
        <mesh
          filename="package://car_4wd/meshes/1_Link.STL" />
      </geometry>
    </collision>
  </link>
  <joint
    name="1_joint"
    type="revolute">
    <origin
      xyz="-0.001338 -0.0057253 0.025"
      rpy="0 0 0" />
    <parent
      link="de_Link" />
    <child
      link="1_Link" />
    <axis
      xyz="0 0 1" />
    <limit
      lower="0"
      upper="0"
      effort="0"
      velocity="0" />
    <dynamics
      damping="0.01"
      friction="0.01" />
  </joint>
  <link
    name="2_link">
    <inertial>
      <origin
        xyz="-0.024115 0.076424 0.0225"
        rpy="0 0 0" />
      <mass
        value="0.53988" />
      <inertia
        ixx="0.0048113"
        ixy="-0.0024174"
        ixz="2.1684E-19"
        iyy="0.0017825"
        iyz="1.8449E-19"
        izz="0.0062046" />
    </inertial>
    <visual>
      <origin
        xyz="0 0 0"
        rpy="0 0 0" />
      <geometry>
        <mesh
          filename="package://car_4wd/meshes/2_link.STL" />
      </geometry>
      <material
        name="">
        <color
          rgba="0.79216 0.81961 0.93333 1" />
      </material>
    </visual>
    <collision>
      <origin
        xyz="0 0 0"
        rpy="0 0 0" />
      <geometry>
        <mesh
          filename="package://car_4wd/meshes/2_link.STL" />
      </geometry>
    </collision>
  </link>
  <joint
    name="2_joint"
    type="revolute">
    <origin
      xyz="0.0064582 0.027635 0.02"
      rpy="1.5708 0 -0.22958" />
    <parent
      link="1_Link" />
    <child
      link="2_link" />
    <axis
      xyz="0 0 1" />
    <limit
      lower="0"
      upper="0"
      effort="0"
      velocity="0" />
    <dynamics
      damping="0.01"
      friction="0.01" />
  </joint>
</robot>