<?xml version="1.0" encoding="utf-8"?>
<!-- This URDF was automatically created by SolidWorks to URDF Exporter! Originally created by Stephen Brawner (brawner@gmail.com) 
     Commit Version: 1.6.0-1-g15f4949  Build Version: 1.6.7594.29634
     For more information, please see http://wiki.ros.org/sw_urdf_exporter -->
<robot
  name="urdf">
  <link
    name="base_link">
    <inertial>
      <origin
        xyz="0.00026343 -1.5535E-11 0.0056311"
        rpy="0 0 0" />
      <mass
        value="0.62938" />
      <inertia
        ixx="0.0021443"
        ixy="5.5259E-11"
        ixz="-1.8826E-05"
        iyy="0.0022725"
        iyz="-4.0514E-15"
        izz="0.0042455" />
    </inertial>
    <visual>
      <origin
        xyz="0 0 0"
        rpy="0 0 0" />
      <geometry>
        <mesh
          filename="package://urdf/meshes/base_link.STL" />
      </geometry>
      <material
        name="">
        <color
          rgba="0.75294 0.75294 0.75294 1" />
      </material>
    </visual>
    <collision>
      <origin
        xyz="0 0 0"
        rpy="0 0 0" />
      <geometry>
        <mesh
          filename="package://urdf/meshes/base_link.STL" />
      </geometry>
    </collision>
  </link>
  <link
    name="rim_front_left_Link">
    <inertial>
      <origin
        xyz="-8.3267E-17 -1.6653E-16 0.013812"
        rpy="0 0 0" />
      <mass
        value="0.045828" />
      <inertia
        ixx="7.9435E-06"
        ixy="1.1537E-20"
        ixz="1.2705E-21"
        iyy="7.9435E-06"
        iyz="9.3167E-21"
        izz="1.5567E-05" />
    </inertial>
    <visual>
      <origin
        xyz="0 0 0"
        rpy="0 0 0" />
      <geometry>
        <mesh
          filename="package://urdf/meshes/rim_front_left_Link.STL" />
      </geometry>
      <material
        name="">
        <color
          rgba="0.79216 0.81961 0.93333 1" />
      </material>
    </visual>
    <collision>
      <origin
        xyz="0 0 0"
        rpy="0 0 0" />
      <geometry>
        <mesh
          filename="package://urdf/meshes/rim_front_left_Link.STL" />
      </geometry>
    </collision>
  </link>
  <joint
    name="rim_front_left_joint"
    type="continuous">
    <origin
      xyz="0.11977 0.12038 -0.0255"
      rpy="1.5708 0 -0.7854" />
    <parent
      link="base_link" />
    <child
      link="rim_front_left_Link" />
    <axis
      xyz="0 0 1" />
    <dynamics
      damping="0.01"
      friction="0.01" />
  </joint>
  <link
    name="roller_e_rim_front_left_link">
    <inertial>
      <origin
        xyz="2.7756E-17 0 0"
        rpy="0 0 0" />
      <mass
        value="0.0066143" />
      <inertia
        ixx="5.5362E-07"
        ixy="-2.647E-23"
        ixz="-3.3796E-09"
        iyy="5.5367E-07"
        iyz="-7.8727E-23"
        izz="3.1857E-07" />
    </inertial>
    <visual>
      <origin
        xyz="0 0 0"
        rpy="0 0 0" />
      <geometry>
        <mesh
          filename="package://urdf/meshes/roller_e_rim_front_left_link.STL" />
      </geometry>
      <material
        name="">
        <color
          rgba="0.29804 0.29804 0.29804 1" />
      </material>
    </visual>
    <collision>
      <origin
        xyz="0 0 0"
        rpy="0 0 0" />
      <geometry>
        <mesh
          filename="package://urdf/meshes/roller_e_rim_front_left_link.STL" />
      </geometry>
    </collision>
  </link>
  <joint
    name="roller_e_rim_front_left_joint"
    type="continuous">
    <origin
      xyz="-0.027497 0.00039526 0.0045"
      rpy="-1.5708 0 0" />
    <parent
      link="rim_front_left_Link" />
    <child
      link="roller_e_rim_front_left_link" />
    <axis
      xyz="0 0 1" />
    <dynamics
      damping="0.01"
      friction="0.01" />
  </joint>
  <link
    name="lidar_Link">
    <inertial>
      <origin
        xyz="0.0082941 0 -0.0085489"
        rpy="0 0 0" />
      <mass
        value="0.1467" />
      <inertia
        ixx="6.2272E-05"
        ixy="-1.6963E-20"
        ixz="1.8866E-05"
        iyy="0.00010967"
        iyz="9.2597E-21"
        izz="0.00012568" />
    </inertial>
    <visual>
      <origin
        xyz="0 0 0"
        rpy="0 0 0" />
      <geometry>
        <mesh
          filename="package://urdf/meshes/lidar_Link.STL" />
      </geometry>
      <material
        name="">
        <color
          rgba="0.79216 0.81961 0.93333 1" />
      </material>
    </visual>
    <collision>
      <origin
        xyz="0 0 0"
        rpy="0 0 0" />
      <geometry>
        <mesh
          filename="package://urdf/meshes/lidar_Link.STL" />
      </geometry>
    </collision>
  </link>
  <joint
    name="lidar_joint"
    type="fixed">
    <origin
      xyz="-0.00711050901810081 0 0.04625"
      rpy="0 0 0" />
    <parent
      link="base_link" />
    <child
      link="lidar_Link" />
    <axis
      xyz="0 0 0" />
    <dynamics
      damping="0.01"
      friction="0.01" />
  </joint>
  <link
    name="cam_Link">
    <inertial>
      <origin
        xyz="-0.001705 -0.0001361 -0.011444"
        rpy="0 0 0" />
      <mass
        value="0.10791" />
      <inertia
        ixx="7.71E-06"
        ixy="2.2103E-10"
        ixz="-1.7837E-08"
        iyy="7.0257E-05"
        iyz="4.9293E-08"
        izz="7.1255E-05" />
    </inertial>
    <visual>
      <origin
        xyz="0 0 0"
        rpy="0 0 0" />
      <geometry>
        <mesh
          filename="package://urdf/meshes/cam_Link.STL" />
      </geometry>
      <material
        name="">
        <color
          rgba="0.89804 0.91765 0.92941 1" />
      </material>
    </visual>
    <collision>
      <origin
        xyz="0 0 0"
        rpy="0 0 0" />
      <geometry>
        <mesh
          filename="package://urdf/meshes/cam_Link.STL" />
      </geometry>
    </collision>
  </link>
  <joint
    name="cam_joint"
    type="fixed">
    <origin
      xyz="0.119389490981904 0.00171624697898104 0.0889999999999961"
      rpy="1.5707963267949 0 1.57079632679488" />
    <parent
      link="base_link" />
    <child
      link="cam_Link" />
    <axis
      xyz="0 0 0" />
    <dynamics
      damping="0.01"
      friction="0.01" />
  </joint>
  <link
    name="gps_Link">
    <inertial>
      <origin
        xyz="-0.00023434 -0.00048018 -0.008094"
        rpy="0 0 0" />
      <mass
        value="0.027335" />
      <inertia
        ixx="3.5557E-06"
        ixy="-1.4936E-08"
        ixz="1.0193E-08"
        iyy="3.6824E-06"
        iyz="-5.5545E-10"
        izz="7.0614E-06" />
    </inertial>
    <visual>
      <origin
        xyz="0 0 0"
        rpy="0 0 0" />
      <geometry>
        <mesh
          filename="package://urdf/meshes/gps_Link.STL" />
      </geometry>
      <material
        name="">
        <color
          rgba="0.75294 0.75294 0.75294 1" />
      </material>
    </visual>
    <collision>
      <origin
        xyz="0 0 0"
        rpy="0 0 0" />
      <geometry>
        <mesh
          filename="package://urdf/meshes/gps_Link.STL" />
      </geometry>
    </collision>
  </link>
  <joint
    name="gps_joint"
    type="fixed">
    <origin
      xyz="-0.101891690887223 0.000123009149377712 0.0281386585309423"
      rpy="0 0 0" />
    <parent
      link="base_link" />
    <child
      link="gps_Link" />
    <axis
      xyz="0 0 0" />
    <dynamics
      damping="0.01"
      friction="0.01" />
  </joint>
  <link
    name="de_Link">
    <inertial>
      <origin
        xyz="0 2.77555756156289E-17 -0.0174830384543071"
        rpy="0 0 0" />
      <mass
        value="0.327529187998142" />
      <inertia
        ixx="0.00036497029704894"
        ixy="2.70901650611047E-20"
        ixz="-4.92055367938496E-20"
        iyy="0.00036497029704894"
        iyz="8.43831343727799E-20"
        izz="0.0006664691117042" />
    </inertial>
    <visual>
      <origin
        xyz="0 0 0"
        rpy="0 0 0" />
      <geometry>
        <mesh
          filename="package://urdf/meshes/de_Link.STL" />
      </geometry>
      <material
        name="">
        <color
          rgba="0.792156862745098 0.819607843137255 0.933333333333333 1" />
      </material>
    </visual>
    <collision>
      <origin
        xyz="0 0 0"
        rpy="0 0 0" />
      <geometry>
        <mesh
          filename="package://urdf/meshes/de_Link.STL" />
      </geometry>
    </collision>
  </link>
  <joint
    name="de_joint"
    type="fixed">
    <origin
      xyz="-0.00061051 0 0.104"
      rpy="0 0 0" />
    <parent
      link="base_link" />
    <child
      link="de_Link" />
    <axis
      xyz="0 0 0" />
    <dynamics
      damping="0.01"
      friction="0.01" />
  </joint>
  <link
    name="1_Link">
    <inertial>
      <origin
        xyz="0.002182 0.0093368 0.020798"
        rpy="0 0 0" />
      <mass
        value="0.09842" />
      <inertia
        ixx="6.5924E-05"
        ixy="-1.4202E-06"
        ixz="6.6287E-08"
        iyy="6.0179E-05"
        iyz="2.8365E-07"
        izz="5.423E-05" />
    </inertial>
    <visual>
      <origin
        xyz="0 0 0"
        rpy="0 0 0" />
      <geometry>
        <mesh
          filename="package://urdf/meshes/1_Link.STL" />
      </geometry>
      <material
        name="">
        <color
          rgba="0.79216 0.81961 0.93333 1" />
      </material>
    </visual>
    <collision>
      <origin
        xyz="0 0 0"
        rpy="0 0 0" />
      <geometry>
        <mesh
          filename="package://urdf/meshes/1_Link.STL" />
      </geometry>
    </collision>
  </link>
  <joint
    name="1_joint"
    type="revolute">
    <origin
      xyz="-0.001338 -0.0057253 0.025"
      rpy="0 0 0" />
    <parent
      link="de_Link" />
    <child
      link="1_Link" />
    <axis
      xyz="0 0 1" />
    <limit
      lower="0"
      upper="0"
      effort="0"
      velocity="0" />
    <dynamics
      damping="0.01"
      friction="0.01" />
  </joint>
  <link
    name="2_link">
    <inertial>
      <origin
        xyz="-0.024115 0.076424 0.0225"
        rpy="0 0 0" />
      <mass
        value="0.53988" />
      <inertia
        ixx="0.0048113"
        ixy="-0.0024174"
        ixz="1.0842E-19"
        iyy="0.0017825"
        iyz="2.387E-19"
        izz="0.0062046" />
    </inertial>
    <visual>
      <origin
        xyz="0 0 0"
        rpy="0 0 0" />
      <geometry>
        <mesh
          filename="package://urdf/meshes/2_link.STL" />
      </geometry>
      <material
        name="">
        <color
          rgba="0.79216 0.81961 0.93333 1" />
      </material>
    </visual>
    <collision>
      <origin
        xyz="0 0 0"
        rpy="0 0 0" />
      <geometry>
        <mesh
          filename="package://urdf/meshes/2_link.STL" />
      </geometry>
    </collision>
  </link>
  <joint
    name="2_joint"
    type="revolute">
    <origin
      xyz="0.0064582 0.027635 0.02"
      rpy="1.5708 0 -0.22958" />
    <parent
      link="1_Link" />
    <child
      link="2_link" />
    <axis
      xyz="0 0 1" />
    <limit
      lower="0"
      upper="0"
      effort="0"
      velocity="0" />
    <dynamics
      damping="0.01"
      friction="0.01" />
  </joint>
</robot>